<?xml version="1.0" encoding="UTF-8"?>
<testsuites>
	<testsuite name="tests.UsersTestCase-20201118092415" tests="10" file="tests.py" time="0.017" timestamp="2020-11-18T09:24:15" failures="3" errors="0" skipped="0">
		<testcase classname="tests.UsersTestCase" name="test_task1_createapp" time="0.001" timestamp="2020-11-18T09:24:15" file="module2\tests.py" line="7">
			<system-out><![CDATA[]]></system-out>
			<system-err><![CDATA[]]></system-err>
		</testcase>
		<testcase classname="tests.UsersTestCase" name="test_task2_add_settings" time="0.001" timestamp="2020-11-18T09:24:15" file="module2\tests.py" line="15">
			<system-out><![CDATA[]]></system-out>
			<system-err><![CDATA[]]></system-err>
		</testcase>
		<testcase classname="tests.UsersTestCase" name="test_task3_add_template" time="0.000" timestamp="2020-11-18T09:24:15" file="module2\tests.py" line="18">
			<system-out><![CDATA[]]></system-out>
			<system-err><![CDATA[]]></system-err>
		</testcase>
		<testcase classname="tests.UsersTestCase" name="test_task4_create_model" time="0.002" timestamp="2020-11-18T09:24:15" file="module2\tests.py" line="22">
			<system-out><![CDATA[]]></system-out>
			<system-err><![CDATA[]]></system-err>
		</testcase>
		<testcase classname="tests.UsersTestCase" name="test_task5_register_admin" time="0.002" timestamp="2020-11-18T09:24:15" file="module2\tests.py" line="40">
			<system-out><![CDATA[]]></system-out>
			<system-err><![CDATA[]]></system-err>
		</testcase>
		<testcase classname="tests.UsersTestCase" name="test_task6_add_settings" time="0.000" timestamp="2020-11-18T09:24:15" file="module2\tests.py" line="73">
			<system-out><![CDATA[]]></system-out>
			<system-err><![CDATA[]]></system-err>
		</testcase>
		<testcase classname="tests.UsersTestCase" name="test_task7_setup_urls" time="0.002" timestamp="2020-11-18T09:24:15" file="module2\tests.py" line="78">
			<system-out><![CDATA[]]></system-out>
			<system-err><![CDATA[]]></system-err>
		</testcase>
		<testcase classname="tests.UsersTestCase" name="test_task10_make_migrations" time="0.006" timestamp="2020-11-18T09:24:15" file="module2\tests.py" line="179">
			<failure type="AssertionError" message="Did you use `manage.py makemigrations` to create the `users` migrations file? Don't forget to `add` it to the git repo."><![CDATA[Traceback (most recent call last):
  File "C:\Users\Daniel\Downloads\python-django-models-authentication\module2\tests.py", line 182, in test_task10_make_migrations
    self.assertTrue(os.path.isfile('users/migrations/0001_initial.py'), msg=msg)
  File "C:\Users\Daniel\Downloads\python-django-models-authentication\support\SimplerTestCase.py", line 12, in assertTrue
    self.fail(msg or (str(expr) + "is not True"))
AssertionError: Did you use `manage.py makemigrations` to create the `users` migrations file? Don't forget to `add` it to the git repo.
]]></failure>
			<system-out><![CDATA[]]></system-out>
			<system-err><![CDATA[]]></system-err>
		</testcase>
		<testcase classname="tests.UsersTestCase" name="test_task8_redirect_routes" time="0.002" timestamp="2020-11-18T09:24:15" file="module2\tests.py" line="143">
			<failure type="AssertionError" message="Did you `include` the users project URLS? in `blogproj/urls.py`?"><![CDATA[Traceback (most recent call last):
  File "C:\Users\Daniel\Downloads\python-django-models-authentication\module2\tests.py", line 167, in test_task8_redirect_routes
    self.assertTrue(users_path_found,  "Did you `include` the users project URLS? in `blogproj/urls.py`?")
  File "C:\Users\Daniel\Downloads\python-django-models-authentication\support\SimplerTestCase.py", line 12, in assertTrue
    self.fail(msg or (str(expr) + "is not True"))
AssertionError: Did you `include` the users project URLS? in `blogproj/urls.py`?
]]></failure>
			<system-out><![CDATA[]]></system-out>
			<system-err><![CDATA[]]></system-err>
		</testcase>
		<testcase classname="tests.UsersTestCase" name="test_task9_update_site_templates" time="0.001" timestamp="2020-11-18T09:24:15" file="module2\tests.py" line="169">
			<failure type="AssertionError" message="There is still a `{% comment %}` tag in `templates/base.html`"><![CDATA[Traceback (most recent call last):
  File "C:\Users\Daniel\Downloads\python-django-models-authentication\module2\tests.py", line 176, in test_task9_update_site_templates
    self.assertTrue(not comment_found, msg="There is still a `{% comment %}` tag in `" + filename + "`")
  File "C:\Users\Daniel\Downloads\python-django-models-authentication\support\SimplerTestCase.py", line 12, in assertTrue
    self.fail(msg or (str(expr) + "is not True"))
AssertionError: There is still a `{% comment %}` tag in `templates/base.html`
]]></failure>
			<system-out><![CDATA[]]></system-out>
			<system-err><![CDATA[]]></system-err>
		</testcase>
	</testsuite>
</testsuites>
